<mujoco model="ur5e scene">
  <compiler angle="radian" meshdir="kuka/assets" autolimits="true"/>

  <statistic center="0.3 0 0.4" extent="0.8"/>

  <visual>
    <headlight diffuse="0.6 0.6 0.6" ambient="0.1 0.1 0.1" specular="0 0 0"/>
    <rgba haze="0.15 0.25 0.35 1"/>
    <global azimuth="120" elevation="-20"/>
  </visual>

  <asset>
    <texture type="skybox" builtin="gradient" rgb1="0.3 0.5 0.7" rgb2="0 0 0" width="512" height="3072"/>
    <texture type="2d" name="groundplane" builtin="checker" mark="edge" rgb1="0.2 0.3 0.4" rgb2="0.1 0.2 0.3" markrgb="0.8 0.8 0.8" width="300" height="300"/>
    <material name="groundplane" texture="groundplane" texuniform="true" texrepeat="5 5" reflectance="0.2"/>
  <material class="iiwa" name="gray" rgba="0.4 0.4 0.4 1"/>
    <material class="iiwa" name="light_gray" rgba="0.6 0.6 0.6 1"/>
    <material class="iiwa" name="black" rgba="0 0 0 1"/>
    <material class="iiwa" name="orange" rgba="1 0.423529 0.0392157 1"/>

    <mesh file="link_0.obj"/>
    <mesh file="link_1.obj"/>
    <mesh file="link_2_orange.obj"/>
    <mesh file="link_2_grey.obj"/>
    <mesh file="link_3.obj"/>
    <mesh file="band.obj"/>
    <mesh file="kuka.obj"/>
    <mesh file="link_4_orange.obj"/>
    <mesh file="link_4_grey.obj"/>
    <mesh file="link_5.obj"/>
    <mesh file="link_6_orange.obj"/>
    <mesh file="link_6_grey.obj"/>
    <mesh file="link_7.obj"/>
  <mesh name="tool_mesh" file="driller.obj"/> 
  <mesh name="aluminium_plate_mesh" file="aluminium_plate.obj"/> 
  <mesh name="guide_mesh" file="Linear_guide.obj"/> 
  </asset>

  <worldbody>
    <light pos="0 0 1.5" dir="0 0 -1" directional="true"/>
    <geom name="floor" size="0 0 0.05" type="plane" material="groundplane"/>
    <!-- Definition of the world frame -->
    <body name="world_frame" pos="0.0 0.0 0.0">
        <geom name="world_x_axis" type="capsule" fromto="0 0 0 0.15 0 0" size="0.01" rgba="1 0 0 1" contype="0" conaffinity="0"/>
        <geom name="world_y_axis" type="capsule" fromto="0 0 0 0 0.15 0" size="0.01" rgba="0 1 0 1" contype="0" conaffinity="0"/>
        <geom name="world_z_axis" type="capsule" fromto="0 0 0 0 0 0.15" size="0.01" rgba="0 0 1 1" contype="0" conaffinity="0"/>
    </body>

  <light name="top" pos="0 0 2" mode="trackcom"/>
    <body name="base" childclass="iiwa">
      <inertial mass="5" pos="-0.1 0 0.07" diaginertia="0.05 0.06 0.03"/>
      <geom class="visual" mesh="link_0"/>
      <geom class="collision" size="0.12" pos="0 0 0.03"/>
      <geom class="collision" size="0.08" pos="-0.08 0 0.103"/>
      <geom class="collision" size="0.08" pos="-0.08 0 0.04"/>
      <geom class="collision" size="0.1" pos="0 0 0.14"/>
      <body name="link1" pos="0 0 0.1575">
        <inertial mass="5.76" pos="0 -0.03 0.12" diaginertia="0.0333 0.033 0.0123"/>
        <joint name="joint1" class="joint1"/>
        <geom class="visual" mesh="link_1"/>
        <geom class="collision" size="0.08" pos="0 0 -0.0005"/>
        <geom class="collision" size="0.075" pos="0.01 -0.025 0.0425"/>
        <geom class="collision" size="0.075" pos="-0.01 -0.025 0.0425"/>
        <geom class="collision" size="0.07" pos="0.01 -0.045 0.1025"/>
        <geom class="collision" size="0.07" pos="-0.01 -0.045 0.1025"/>
        <body name="link2" pos="0 0 0.2025" quat="0 0 1 1">
          <inertial mass="6.35" pos="0.0003 0.059 0.042" diaginertia="0.0305 0.0304 0.011" quat="0 0 1 1"/>
          <joint name="joint2" class="joint2"/>
          <geom class="visual" material="orange" mesh="link_2_orange"/>
          <geom class="visual" mesh="link_2_grey"/>
          <geom class="collision" size="0.095" pos="0 0 -0.01"/>
          <geom class="collision" size="0.09" pos="0 0 0.045"/>
          <geom class="collision" size="0.07" pos="-0.01 0.04 0.054"/>
          <geom class="collision" size="0.065" pos="-0.01 0.09 0.04"/>
          <geom class="collision" size="0.065" pos="-0.01 0.13 0.02"/>
          <geom class="collision" size="0.07" pos="0.01 0.04 0.054"/>
          <geom class="collision" size="0.065" pos="0.01 0.09 0.04"/>
          <geom class="collision" size="0.065" pos="0.01 0.13 0.02"/>
          <geom class="collision" size="0.075" pos="0 0.18 0"/>
          <body name="link3" pos="0 0.2045 0" quat="0 0 1 1">
            <inertial mass="3.5" pos="0 0.03 0.13" diaginertia="0.025 0.0238 0.0076"/>
            <joint name="joint3" class="joint1"/>
            <geom class="visual" mesh="link_3"/>
            <geom class="visual" material="light_gray" mesh="band"/>
            <geom class="visual" material="black" mesh="kuka"/>
            <geom class="collision" size="0.075" pos="0 0 0.0355"/>
            <geom class="collision" size="0.06" pos="0.01 0.023 0.0855"/>
            <geom class="collision" size="0.055" pos="0.01 0.048 0.1255"/>
            <geom class="collision" size="0.06" pos="0.01 0.056 0.1755"/>
            <geom class="collision" size="0.06" pos="-0.01 0.023 0.0855"/>
            <geom class="collision" size="0.055" pos="-0.01 0.048 0.1255"/>
            <geom class="collision" size="0.06" pos="-0.01 0.056 0.1755"/>
            <geom class="collision" size="0.075" pos="0 0.045 0.2155"/>
            <geom class="collision" size="0.075" pos="0 0 0.2155"/>
            <body name="link4" pos="0 0 0.2155" quat="1 1 0 0">
              <inertial mass="3.5" pos="0 0.067 0.034" diaginertia="0.017 0.0164 0.006" quat="1 1 0 0"/>
              <joint name="joint4" class="joint2"/>
              <geom class="visual" material="orange" mesh="link_4_orange"/>
              <geom class="visual" mesh="link_4_grey"/>
              <geom class="collision" size="0.078" pos="0 0.01 0.046"/>
              <geom class="collision" size="0.06" pos="0.01 0.06 0.052"/>
              <geom class="collision" size="0.065" pos="0.01 0.12 0.034"/>
              <geom class="collision" size="0.06" pos="-0.01 0.06 0.052"/>
              <geom class="collision" size="0.065" pos="-0.01 0.12 0.034"/>
              <geom class="collision" size="0.075" pos="0 0.184 0"/>
              <body name="link5" pos="0 0.1845 0" quat="0 0 1 1">
                <inertial mass="3.5" pos="0.0001 0.021 0.076" diaginertia="0.01 0.0087 0.00449"/>
                <joint name="joint5" class="joint1"/>
                <geom class="visual" mesh="link_5"/>
                <geom class="visual" material="light_gray" mesh="band"/>
                <geom class="visual" material="black" mesh="kuka"/>
                <geom class="collision" size="0.075" pos="0 0 0.0335"/>
                <geom class="collision" size="0.05" pos="-0.012 0.031 0.0755"/>
                <geom class="collision" size="0.05" pos="0.012 0.031 0.0755"/>
                <geom class="collision" size="0.04" pos="-0.012 0.06 0.1155"/>
                <geom class="collision" size="0.04" pos="0.012 0.06 0.1155"/>
                <geom class="collision" size="0.04" pos="-0.01 0.065 0.1655"/>
                <geom class="collision" size="0.04" pos="0.01 0.065 0.1655"/>
                <geom class="collision" size="0.035" pos="-0.012 0.065 0.1855"/>
                <geom class="collision" size="0.035" pos="0.012 0.065 0.1855"/>
                <body name="link6" pos="0 0 0.2155" quat="1 1 0 0">
                  <inertial mass="1.8" pos="0 0.0006 0.0004" diaginertia="0.0049 0.0047 0.0036" quat="1 1 0 0"/>
                  <joint name="joint6" class="joint2"/>
                  <geom class="visual" material="orange" mesh="link_6_orange"/>
                  <geom class="visual" mesh="link_6_grey"/>
                  <geom class="collision" size="0.055" pos="0 0 -0.059"/>
                  <geom class="collision" size="0.065" pos="0 -0.03 0.011"/>
                  <geom class="collision" size="0.08"/>
                  <body name="link7" pos="0 0.081 0" quat="0 0 1 1">
                    <inertial mass="1.2" pos="0 0 0.02" diaginertia="0.001 0.001 0.001"/>
                    <!-- Reference frame: wrist_3_link -->
                    <geom type="capsule" fromto="0 0 0 0.08 0 0" rgba="1 0 0 1" size="0.003" contype="0" conaffinity="0"/>
                    <geom type="capsule" fromto="0 0 0 0 0.08 0" rgba="0 1 0 1" size="0.003" contype="0" conaffinity="0"/>
                    <geom type="capsule" fromto="0 0 0 0 0 0.08" rgba="0 0 1 1" size="0.003" contype="0" conaffinity="0"/>
                    <joint name="joint7" class="joint3"/>
                    <geom class="visual" mesh="link_7"/>
                    <geom class="collision" size="0.06" pos="0 0 0.001"/>
                    <site pos="0 0 0.045" name="attachment_site"/>
                    <geom type="capsule" fromto="0 0 0 0.05 0 0" rgba="1 0 0 1" size="0.002" contype="0" conaffinity="0"/>
                    <geom type="capsule" fromto="0 0 0 0 0.05 0" rgba="0 1 0 1" size="0.002" contype="0" conaffinity="0"/>
                    <geom type="capsule" fromto="0 0 0 0 0 0.05" rgba="0 0 1 1" size="0.002" contype="0" conaffinity="0"/>
                    <body name="ee_frame_visual_only" pos="0 0 0.045">
                      <geom type="capsule" fromto="0 0 0 0.05 0 0" rgba="1 0 0 1" size="0.002" contype="0" conaffinity="0"/>
                      <geom type="capsule" fromto="0 0 0 0 0.05 0" rgba="0 1 0 1" size="0.002" contype="0" conaffinity="0"/>
                      <geom type="capsule" fromto="0 0 0 0 0 0.05" rgba="0 0 1 1" size="0.002" contype="0" conaffinity="0"/> 
                      <!-- The tool is imported by a python code -->
                      
                      
                      <!-- Reference frame attached @ tool tip for screwing (T) -->
                      <body name="tool_frame" pos="0 0 0" quat="1 0 0 0">
                        <site name="tool_site" pos="0 0 0" quat="1 0 0 0"/>
                        <geom type="capsule" fromto="0 0 0 0.06 0 0" rgba="1 0 0 1" size="0.003" contype="0" conaffinity="0"/>
                        <geom type="capsule" fromto="0 0 0 0 0.06 0" rgba="0 1 0 1" size="0.003" contype="0" conaffinity="0"/>
                        <geom type="capsule" fromto="0 0 0 0 0 0.06" rgba="0 0 1 1" size="0.003" contype="0" conaffinity="0"/>
                    </body>
                  <body name="tool_top" pos="0 0 0">
      <inertial mass="3.75" pos="0 0 0.1" diaginertia="0.021 0.021 0.003"/>
      <geom type="mesh" mesh="tool_mesh" rgba="0.2 0.2 0.2 1" contype="0" conaffinity="0" group="0"/>
      <!-- collision cylinder -->
      <geom name="driller" type="cylinder" size="0.035 0.125" pos="0 0 0.125" rgba="0.2 0.8 0.2 1" contype="1" conaffinity="1" group="3"/>
      <!-- Marker (red sphere) to specify the origin -->
      <site name="mount_site" pos="0 0 0" size="0.005" rgba="1 0 0 1"/>
      <!-- Marker (green sphere) to specify the point of application of the weight -->
      <geom type="sphere" size="0.005" pos="0 0 0.1" rgba="0 1 0 1" contype="0" conaffinity="0" group="2"/>
    </body>
  </body>
                  </body>
                </body>
              </body>
            </body>
          </body>
        </body>
      </body>
    </body>
  <body name="aluminium_plate" pos="0 0 0">

      <geom type="mesh" mesh="aluminium_plate_mesh" rgba="0.45 0.45 0.45 1" contype="0" conaffinity="0" group="0"/>
      <!-- Base plate -->
      <geom name="base_plate" type="box" size="0.4 0.75 0.025" pos="0 0 0.025" rgba="0.8 0.2 0.2 1" contype="1" conaffinity="1" group="3"/>

      <!-- right top cube -->
      <geom name="right_top_cube" type="box" size="0.0755 0.485 0.025" pos="-0.226 0.141 0.075" rgba="0.2 0.8 0.2 1" contype="1" conaffinity="1" group="3"/>

      <!-- right middle cube -->
      <geom name="right_middle_cube" type="box" size="0.1205 0.2835 0.025" pos="-0.03 0.202 0.075" rgba="0.2 0.8 0.2 1" contype="1" conaffinity="1" group="3"/>

      <!-- right bottom cube -->
      <geom name="right_bottom_cube" type="box" size="0.051 0.2835 0.025" pos="0.141 0.202 0.075" rgba="0.2 0.8 0.2 1" contype="1" conaffinity="1" group="3"/>

      <!-- lower bottom cube -->
      <geom name="lower_bottom_cube" type="box" size="0.0295 0.285 0.025" pos="0.284 -0.367 0.075" rgba="0.2 0.8 0.2 1" contype="1" conaffinity="1" group="3"/>

      <!-- lower top cube -->
      <geom name="lower_top_cube" type="box" size="0.0705 0.0295 0.025" pos="0.184 -0.622 0.075" rgba="0.2 0.8 0.2 1" contype="1" conaffinity="1" group="3"/>

      <!-- left cylinder -->
      <geom name="left_cylinder" type="cylinder" size="0.05 0.01" pos="0 -0.373 0.06" rgba="0.2 0.8 0.2 1" contype="1" conaffinity="1" group="3"/>

      <!-- right cylinder -->
      <geom name="right_cylinder" type="cylinder" size="0.05 0.01" pos="0.317 0.583 0.06" rgba="0.2 0.8 0.2 1" contype="1" conaffinity="1" group="3"/>


      <!-- Definition of the sites -->
      <!-- center of the piece -->
      <site name="mount_plate_site" pos="0.0 0.0 0.0" size="0.005" rgba="1 0 0 1"/>

      <!-- Hole 1 -->
      <body name="hole_1_frame_body" pos="0 -0.373 0.07" quat="0 1 0 0">
        <geom type="capsule" fromto="0 0 0 0.08 0 0" rgba="1 0 0 1" size="0.003" contype="0" conaffinity="0"/>
        <geom type="capsule" fromto="0 0 0 0 0.08 0" rgba="0 1 0 1" size="0.003" contype="0" conaffinity="0"/>
        <geom type="capsule" fromto="0 0 0 0 0 0.08" rgba="0 0 1 1" size="0.003" contype="0" conaffinity="0"/>
      </body>

      <!-- Hole 2 -->
      <body name="hole_2_frame_body" pos="0.317 0.583 0.07" quat="0 1 0 0">
        <geom type="capsule" fromto="0 0 0 0.08 0 0" rgba="1 0 0 1" size="0.003" contype="0" conaffinity="0"/>
        <geom type="capsule" fromto="0 0 0 0 0.08 0" rgba="0 1 0 1" size="0.003" contype="0" conaffinity="0"/>
        <geom type="capsule" fromto="0 0 0 0 0 0.08" rgba="0 0 1 1" size="0.003" contype="0" conaffinity="0"/>
      </body>


    </body>   
  <body name="obstacle_body" pos="0 0 0">
      <inertial mass="624" pos="0 0 0.05" diaginertia="208.52 8.84 216.32"/>
      <geom type="mesh" mesh="guide_mesh" rgba="0.2 0.2 0.2 1" contype="0" conaffinity="0" group="0"/>
      <!-- collision cylinder -->
      <geom name="base_plate_guide" type="box" size="0.2 1 0.05" pos="0 0 0.05" rgba="0.8 0.2 0.2 1" contype="1" conaffinity="1" group="3"/>
      <!-- Marker (red sphere) to specify the origin -->
      <site name="mount_site_guide" pos="0 0 0" size="0.005" rgba="1 0 0 1"/>
      <!-- Marker (green sphere) to specify the point of application of the weight -->
      <geom type="sphere" size="0.005" pos="0 0 0.05" rgba="0 1 0 1" contype="0" conaffinity="0" group="2"/>
    </body>
  </worldbody>

<default><default class="iiwa">
      <material specular="0.5" shininess="0.25"/>
      <joint axis="0 0 1"/>
      <general gaintype="fixed" biastype="affine" gainprm="2000" biasprm="0 -2000 -200"/>
      <default class="joint1">
        <joint range="-2.96706 2.96706"/>
        <general ctrlrange="-2.96706 2.96706"/>
        <default class="joint2">
          <joint range="-2.0944 2.0944"/>
          <general ctrlrange="-2.0944 2.0944"/>
        </default>
      </default>
      <default class="joint3">
        <joint range="-3.05433 3.05433"/>
        <general ctrlrange="-3.05433 3.05433"/>
      </default>
      <default class="visual">
        <geom type="mesh" contype="0" conaffinity="0" group="2" material="gray"/>
      </default>
      <default class="collision">
        <geom group="3"/>
      </default>
      <site size="0.001" rgba="1 0 0 1" group="4"/>
    </default>
  <geom condim="3" friction="1 0.5 0.01" solref="0.02 1" solimp="0.9 0.95 0.001"/>
  </default><actuator><motor joint="joint1" gear="1"/>
    <motor joint="joint2" gear="1"/>
    <motor joint="joint3" gear="1"/>
    <motor joint="joint4" gear="1"/>
    <motor joint="joint5" gear="1"/>
    <motor joint="joint6" gear="1"/>
    <motor joint="joint7" gear="1"/>
  </actuator></mujoco>
